<?xml version="1.0" encoding="UTF-8"?>
<!-- Generated by org.testng.reporters.JUnitReportReporter -->
<testsuite hostname="sys" name="testPrograms.HashandEqualsTest" tests="4" failures="2" timestamp="3 Sep 2015 19:37:33 GMT" time="0.012" errors="0">
  <testcase name="PositiveTest" time="0.000" classname="testPrograms.HashandEqualsTest"/>
  <testcase name="HashTest" time="0.012" classname="testPrograms.HashandEqualsTest">
    <failure type="java.lang.AssertionError" message="expected [73771720] but found [73771720]">
      <![CDATA[java.lang.AssertionError: expected [73771720] but found [73771720]
	at org.testng.Assert.fail(Assert.java:94)
	at org.testng.Assert.failNotSame(Assert.java:492)
	at org.testng.Assert.assertSame(Assert.java:443)
	at org.testng.Assert.assertSame(Assert.java:453)
	at testPrograms.HashandEqualsTest.HashTest(HashandEqualsTest.java:34)
	at sun.reflect.NativeMethodAccessorImpl.invoke0(Native Method)
	at sun.reflect.NativeMethodAccessorImpl.invoke(Unknown Source)
	at sun.reflect.DelegatingMethodAccessorImpl.invoke(Unknown Source)
	at java.lang.reflect.Method.invoke(Unknown Source)
	at org.testng.internal.MethodInvocationHelper.invokeMethod(MethodInvocationHelper.java:85)
	at org.testng.internal.Invoker.invokeMethod(Invoker.java:639)
	at org.testng.internal.Invoker.invokeTestMethod(Invoker.java:816)
	at org.testng.internal.Invoker.invokeTestMethods(Invoker.java:1124)
	at org.testng.internal.TestMethodWorker.invokeTestMethods(TestMethodWorker.java:124)
	at org.testng.internal.TestMethodWorker.run(TestMethodWorker.java:108)
	at org.testng.TestRunner.privateRun(TestRunner.java:773)
	at org.testng.TestRunner.run(TestRunner.java:623)
	at org.testng.SuiteRunner.runTest(SuiteRunner.java:359)
	at org.testng.SuiteRunner.runSequentially(SuiteRunner.java:354)
	at org.testng.SuiteRunner.privateRun(SuiteRunner.java:312)
	at org.testng.SuiteRunner.run(SuiteRunner.java:261)
	at org.testng.SuiteRunnerWorker.runSuite(SuiteRunnerWorker.java:52)
	at org.testng.SuiteRunnerWorker.run(SuiteRunnerWorker.java:86)
	at org.testng.TestNG.runSuitesSequentially(TestNG.java:1185)
	at org.testng.TestNG.runSuitesLocally(TestNG.java:1110)
	at org.testng.TestNG.run(TestNG.java:1018)
	at org.testng.remote.RemoteTestNG.run(RemoteTestNG.java:112)
	at org.testng.remote.RemoteTestNG.initAndRun(RemoteTestNG.java:205)
	at org.testng.remote.RemoteTestNG.main(RemoteTestNG.java:176)
]]>
    </failure>
  </testcase> <!-- HashTest -->
  <testcase name="HashTest1" time="0.000" classname="testPrograms.HashandEqualsTest">
    <failure type="java.lang.AssertionError" message="expected [x] but found []">
      <![CDATA[java.lang.AssertionError: expected [x] but found []
	at org.testng.Assert.fail(Assert.java:94)
	at org.testng.Assert.failNotEquals(Assert.java:496)
	at org.testng.Assert.assertEquals(Assert.java:125)
	at org.testng.Assert.assertEquals(Assert.java:178)
	at org.testng.Assert.assertEquals(Assert.java:188)
	at testPrograms.HashandEqualsTest.HashTest1(HashandEqualsTest.java:48)
	at sun.reflect.NativeMethodAccessorImpl.invoke0(Native Method)
	at sun.reflect.NativeMethodAccessorImpl.invoke(Unknown Source)
	at sun.reflect.DelegatingMethodAccessorImpl.invoke(Unknown Source)
	at java.lang.reflect.Method.invoke(Unknown Source)
	at org.testng.internal.MethodInvocationHelper.invokeMethod(MethodInvocationHelper.java:85)
	at org.testng.internal.Invoker.invokeMethod(Invoker.java:639)
	at org.testng.internal.Invoker.invokeTestMethod(Invoker.java:816)
	at org.testng.internal.Invoker.invokeTestMethods(Invoker.java:1124)
	at org.testng.internal.TestMethodWorker.invokeTestMethods(TestMethodWorker.java:124)
	at org.testng.internal.TestMethodWorker.run(TestMethodWorker.java:108)
	at org.testng.TestRunner.privateRun(TestRunner.java:773)
	at org.testng.TestRunner.run(TestRunner.java:623)
	at org.testng.SuiteRunner.runTest(SuiteRunner.java:359)
	at org.testng.SuiteRunner.runSequentially(SuiteRunner.java:354)
	at org.testng.SuiteRunner.privateRun(SuiteRunner.java:312)
	at org.testng.SuiteRunner.run(SuiteRunner.java:261)
	at org.testng.SuiteRunnerWorker.runSuite(SuiteRunnerWorker.java:52)
	at org.testng.SuiteRunnerWorker.run(SuiteRunnerWorker.java:86)
	at org.testng.TestNG.runSuitesSequentially(TestNG.java:1185)
	at org.testng.TestNG.runSuitesLocally(TestNG.java:1110)
	at org.testng.TestNG.run(TestNG.java:1018)
	at org.testng.remote.RemoteTestNG.run(RemoteTestNG.java:112)
	at org.testng.remote.RemoteTestNG.initAndRun(RemoteTestNG.java:205)
	at org.testng.remote.RemoteTestNG.main(RemoteTestNG.java:176)
]]>
    </failure>
  </testcase> <!-- HashTest1 -->
  <testcase name="NegativeTest" time="0.000" classname="testPrograms.HashandEqualsTest"/>
</testsuite> <!-- testPrograms.HashandEqualsTest -->
